iadsstgapphost02
*** Found local files:
***   * Airflow/logs/dag_id=B2_Sat_Download_Worker/run_id=manual__2025-02-06T09:36:55.136711+00:00/task_id=sat_download_sub_worker/map_index=0/attempt=1.log
[2025-02-06T09:37:03.726+0000] {taskinstance.py:1094} DEBUG - previous_execution_date was called
[2025-02-06T09:37:03.769+0000] {__init__.py:51} DEBUG - Loading core task runner: StandardTaskRunner
[2025-02-06T09:37:03.801+0000] {taskinstance.py:1094} DEBUG - previous_execution_date was called
[2025-02-06T09:37:03.807+0000] {base_task_runner.py:68} DEBUG - Planning to run as the  user
[2025-02-06T09:37:03.810+0000] {taskinstance.py:844} DEBUG - Refreshing TaskInstance <TaskInstance: B2_Sat_Download_Worker.sat_download_sub_worker manual__2025-02-06T09:36:55.136711+00:00 map_index=0 [queued]> from DB
[2025-02-06T09:37:03.841+0000] {taskinstance.py:1168} DEBUG - <TaskInstance: B2_Sat_Download_Worker.sat_download_sub_worker manual__2025-02-06T09:36:55.136711+00:00 map_index=0 [queued]> dependency 'Task Instance State' PASSED: True, Task state queued was valid.
[2025-02-06T09:37:03.848+0000] {taskinstance.py:1168} DEBUG - <TaskInstance: B2_Sat_Download_Worker.sat_download_sub_worker manual__2025-02-06T09:36:55.136711+00:00 map_index=0 [queued]> dependency 'Previous Dagrun State' PASSED: True, The task did not have depends_on_past set.
[2025-02-06T09:37:03.849+0000] {taskinstance.py:1168} DEBUG - <TaskInstance: B2_Sat_Download_Worker.sat_download_sub_worker manual__2025-02-06T09:36:55.136711+00:00 map_index=0 [queued]> dependency 'Task Instance Not Running' PASSED: True, Task is not in running state.
[2025-02-06T09:37:03.849+0000] {taskinstance.py:1168} DEBUG - <TaskInstance: B2_Sat_Download_Worker.sat_download_sub_worker manual__2025-02-06T09:36:55.136711+00:00 map_index=0 [queued]> dependency 'Task has been mapped' PASSED: True, The task has been mapped
[2025-02-06T09:37:03.849+0000] {taskinstance.py:1168} DEBUG - <TaskInstance: B2_Sat_Download_Worker.sat_download_sub_worker manual__2025-02-06T09:36:55.136711+00:00 map_index=0 [queued]> dependency 'Not In Retry Period' PASSED: True, The task instance was not marked for retrying.
[2025-02-06T09:37:03.849+0000] {taskinstance.py:1159} INFO - Dependencies all met for dep_context=non-requeueable deps ti=<TaskInstance: B2_Sat_Download_Worker.sat_download_sub_worker manual__2025-02-06T09:36:55.136711+00:00 map_index=0 [queued]>
[2025-02-06T09:37:03.855+0000] {taskinstance.py:1168} DEBUG - <TaskInstance: B2_Sat_Download_Worker.sat_download_sub_worker manual__2025-02-06T09:36:55.136711+00:00 map_index=0 [queued]> dependency 'Previous Dagrun State' PASSED: True, The task did not have depends_on_past set.
[2025-02-06T09:37:03.860+0000] {taskinstance.py:1168} DEBUG - <TaskInstance: B2_Sat_Download_Worker.sat_download_sub_worker manual__2025-02-06T09:36:55.136711+00:00 map_index=0 [queued]> dependency 'Pool Slots Available' PASSED: True, There are enough open slots in default_pool to execute the task
[2025-02-06T09:37:03.860+0000] {taskinstance.py:1168} DEBUG - <TaskInstance: B2_Sat_Download_Worker.sat_download_sub_worker manual__2025-02-06T09:36:55.136711+00:00 map_index=0 [queued]> dependency 'Task Concurrency' PASSED: True, Task concurrency is not set.
[2025-02-06T09:37:03.860+0000] {taskinstance.py:1168} DEBUG - <TaskInstance: B2_Sat_Download_Worker.sat_download_sub_worker manual__2025-02-06T09:36:55.136711+00:00 map_index=0 [queued]> dependency 'Task has been mapped' PASSED: True, The task has been mapped
[2025-02-06T09:37:03.860+0000] {taskinstance.py:1168} DEBUG - <TaskInstance: B2_Sat_Download_Worker.sat_download_sub_worker manual__2025-02-06T09:36:55.136711+00:00 map_index=0 [queued]> dependency 'Not In Retry Period' PASSED: True, The task instance was not marked for retrying.
[2025-02-06T09:37:03.860+0000] {taskinstance.py:1159} INFO - Dependencies all met for dep_context=requeueable deps ti=<TaskInstance: B2_Sat_Download_Worker.sat_download_sub_worker manual__2025-02-06T09:36:55.136711+00:00 map_index=0 [queued]>
[2025-02-06T09:37:03.860+0000] {taskinstance.py:1361} INFO - Starting attempt 1 of 1
[2025-02-06T09:37:03.875+0000] {taskinstance.py:1382} INFO - Executing <Mapped(_PythonDecoratedOperator): sat_download_sub_worker> on 2025-02-06 09:36:55.136711+00:00
[2025-02-06T09:37:03.883+0000] {standard_task_runner.py:57} INFO - Started process 2332531 to run task
[2025-02-06T09:37:03.893+0000] {standard_task_runner.py:84} INFO - Running: ['airflow', 'tasks', 'run', 'B2_Sat_Download_Worker', 'sat_download_sub_worker', 'manual__2025-02-06T09:36:55.136711+00:00', '--job-id', '303503', '--raw', '--subdir', '/home/ladsadmin/FGICWebApp/Airflow/dags/b2_sat_download_worker.py', '--cfg-path', '/tmp/tmp51l30qjo', '--map-index', '0']
[2025-02-06T09:37:03.895+0000] {standard_task_runner.py:85} INFO - Job 303503: Subtask sat_download_sub_worker
[2025-02-06T09:37:03.896+0000] {cli_action_loggers.py:67} DEBUG - Calling callbacks: [<function default_action_log at 0x7f375290bf40>]
[2025-02-06T09:37:03.982+0000] {taskinstance.py:1094} DEBUG - previous_execution_date was called
[2025-02-06T09:37:03.990+0000] {task_command.py:416} INFO - Running <TaskInstance: B2_Sat_Download_Worker.sat_download_sub_worker manual__2025-02-06T09:36:55.136711+00:00 map_index=0 [running]> on host iadsstgapphost02
[2025-02-06T09:37:03.990+0000] {settings.py:373} DEBUG - Disposing DB connection pool (PID 2332531)
[2025-02-06T09:37:03.990+0000] {settings.py:234} DEBUG - Setting up DB connection pool (PID 2332531)
[2025-02-06T09:37:03.991+0000] {settings.py:305} DEBUG - settings.prepare_engine_args(): Using NullPool
[2025-02-06T09:37:03.992+0000] {taskinstance.py:844} DEBUG - Refreshing TaskInstance <TaskInstance: B2_Sat_Download_Worker.sat_download_sub_worker manual__2025-02-06T09:36:55.136711+00:00 map_index=0 [running]> from DB
[2025-02-06T09:37:04.077+0000] {taskinstance.py:1094} DEBUG - previous_execution_date was called
[2025-02-06T09:37:04.086+0000] {taskinstance.py:925} DEBUG - Clearing XCom data
[2025-02-06T09:37:04.136+0000] {retries.py:93} DEBUG - Running RenderedTaskInstanceFields.write with retries. Try 1 of 3
[2025-02-06T09:37:04.181+0000] {retries.py:93} DEBUG - Running RenderedTaskInstanceFields._do_delete_old_records with retries. Try 1 of 3
[2025-02-06T09:37:04.209+0000] {taskinstance.py:1662} INFO - Exporting env vars: AIRFLOW_CTX_DAG_OWNER='airflow' AIRFLOW_CTX_DAG_ID='B2_Sat_Download_Worker' AIRFLOW_CTX_TASK_ID='sat_download_sub_worker' AIRFLOW_CTX_EXECUTION_DATE='2025-02-06T09:36:55.136711+00:00' AIRFLOW_CTX_TRY_NUMBER='1' AIRFLOW_CTX_DAG_RUN_ID='manual__2025-02-06T09:36:55.136711+00:00'
[2025-02-06T09:37:04.209+0000] {__init__.py:116} DEBUG - Preparing lineage inlets and outlets
[2025-02-06T09:37:04.210+0000] {__init__.py:157} DEBUG - inlets: [], outlets: []
[2025-02-06T09:37:04.210+0000] {b2_sat_download_worker.py:31} INFO - Satellite Download worker started its work.
[2025-02-06T09:37:05.011+0000] {_base_logger.py:66} DEBUG - {"worker": "SatDownloadWorker", "msg": "Checking if the item is already downloaded or not.", "level": "DEBUG", "sat_image_tile": "SatelliteImageTile object (74)"}
[2025-02-06T09:37:05.015+0000] {_base_logger.py:40} INFO - {"worker": "SatDownloadWorker", "msg": "Now Starting SatDownloadWorker.", "level": "INFO", "sat_image_tile": "SatelliteImageTile object (74)"}
[2025-02-06T09:37:05.017+0000] {_base_logger.py:66} DEBUG - {"worker": "SatDownloadWorker", "msg": "Reached at the 'process_started_worker' Method & About to Execute.", "level": "DEBUG", "sat_image_tile": "SatelliteImageTile object (74)"}
[2025-02-06T09:37:05.019+0000] {_base_logger.py:40} INFO - {"worker": "SatDownloadWorker", "msg": "Well Done!! SatDownloadWorker Started.", "level": "INFO", "sat_image_tile": "SatelliteImageTile object (74)"}
[2025-02-06T09:37:05.022+0000] {_base_logger.py:66} DEBUG - {"worker": "SatDownloadWorker", "msg": "Create an instance of SatelliteImageTileService.", "level": "DEBUG", "sat_image_tile": "SatelliteImageTile object (74)"}
[2025-02-06T09:37:05.024+0000] {_base_logger.py:66} DEBUG - {"worker": "SatDownloadWorker", "msg": "Checking if Source Data exists for the Satellite Tile image.", "level": "DEBUG", "sat_image_tile": "SatelliteImageTile object (74)"}
[2025-02-06T09:37:05.027+0000] {_base_logger.py:66} DEBUG - {"worker": "SatDownloadWorker", "msg": "Calling get_file_name method from service class to get source dataset name.", "level": "DEBUG", "sat_image_tile": "SatelliteImageTile object (74)"}
[2025-02-06T09:37:05.029+0000] {_base_logger.py:66} DEBUG - {"worker": "SentinelImageTileService", "msg": "Verifying whether the satellite image tile corresponds to the Sentinel or Landsat product type.", "level": "DEBUG", "sat_image_tile": "SatelliteImageTile object (74)"}
[2025-02-06T09:37:05.031+0000] {_base_logger.py:66} DEBUG - {"worker": "SentinelImageTileService", "msg": "return file name for Sentinel image tile.", "level": "DEBUG", "sat_image_tile": "SatelliteImageTile object (74)"}
[2025-02-06T09:37:05.033+0000] {_base_logger.py:66} DEBUG - {"worker": "SatDownloadWorker", "msg": "get_file_name method from service class executed Successfully.", "level": "DEBUG", "sat_image_tile": "SatelliteImageTile object (74)"}
[2025-02-06T09:37:05.035+0000] {_base_logger.py:66} DEBUG - {"worker": "SatDownloadWorker", "msg": "Generating Source Dataset Path.", "level": "DEBUG", "sat_image_tile": "SatelliteImageTile object (74)"}
[2025-02-06T09:37:05.040+0000] {_base_logger.py:66} DEBUG - {"worker": "SatDownloadWorker", "msg": "Source Data Created Successfully.", "level": "DEBUG", "source_data": "S2B_MSIL1C_20240714T065619_N0510_R063_T40QBM_20240714T084853.zip", "sat_image_tile": "SatelliteImageTile object (74)"}
[2025-02-06T09:37:05.047+0000] {_base_logger.py:66} DEBUG - {"worker": "SatDownloadWorker", "msg": "Source Data ID set to 274 for sat_image_tile and Saved Successfully.", "level": "DEBUG", "source_data": "S2B_MSIL1C_20240714T065619_N0510_R063_T40QBM_20240714T084853.zip", "sat_image_tile": "SatelliteImageTile object (74)"}
[2025-02-06T09:37:05.051+0000] {_base_logger.py:40} INFO - {"worker": "SatDownloadWorker", "msg": "Downloading Satellite image tile.", "level": "INFO", "source_data": "S2B_MSIL1C_20240714T065619_N0510_R063_T40QBM_20240714T084853.zip", "sat_image_tile": "SatelliteImageTile object (74)"}
[2025-02-06T09:37:05.053+0000] {_base_logger.py:66} DEBUG - {"worker": "SentinelImageTileService", "msg": "Verifying whether the satellite image tile corresponds to the Sentinel or Landsat product type.", "level": "DEBUG", "source_data": "S2B_MSIL1C_20240714T065619_N0510_R063_T40QBM_20240714T084853.zip", "sat_image_tile": "SatelliteImageTile object (74)"}
[2025-02-06T09:37:05.055+0000] {_base_logger.py:66} DEBUG - {"worker": "SentinelImageTileService", "msg": "Product type is Sentinel hence calling sentinel service download.", "level": "DEBUG", "source_data": "S2B_MSIL1C_20240714T065619_N0510_R063_T40QBM_20240714T084853.zip", "sat_image_tile": "SatelliteImageTile object (74)"}
[2025-02-06T09:37:05.060+0000] {_base_logger.py:40} INFO - {"worker": "SentinelImageTileService", "msg": "Downloading Sentinel image tile.", "level": "INFO", "source_data": "S2B_MSIL1C_20240714T065619_N0510_R063_T40QBM_20240714T084853.zip", "sat_image_tile": "SatelliteImageTile object (74)"}
[2025-02-06T09:37:05.064+0000] {_base_logger.py:66} DEBUG - {"worker": "SentinelImageTileService", "msg": "Creating temporary file for JSON data.", "level": "DEBUG", "source_data": "S2B_MSIL1C_20240714T065619_N0510_R063_T40QBM_20240714T084853.zip", "sat_image_tile": "SatelliteImageTile object (74)"}
[2025-02-06T09:37:05.066+0000] {_base_logger.py:66} DEBUG - {"worker": "SentinelImageTileService", "msg": "Temporary file created: /tmp/tmp33u5pbgt", "level": "DEBUG", "source_data": "S2B_MSIL1C_20240714T065619_N0510_R063_T40QBM_20240714T084853.zip", "sat_image_tile": "SatelliteImageTile object (74)"}
[2025-02-06T09:37:05.554+0000] {logging_mixin.py:154} WARNING - 2025-02-06 09:37:05,554 eodag.config                     [DEBUG   ] (tid=139875640009152) Loading configuration from /home/ladsadmin/FGICWebApp/venv/lib/python3.10/site-packages/eodag/resources/providers.yml
[2025-02-06T09:37:05.554+0000] {config.py:251} DEBUG - Loading configuration from /home/ladsadmin/FGICWebApp/venv/lib/python3.10/site-packages/eodag/resources/providers.yml
[2025-02-06T09:37:07.329+0000] {logging_mixin.py:154} WARNING - 2025-02-06 09:37:07,329 eodag.config                     [DEBUG   ] (tid=139875640009152) Loading configuration from /home/ladsadmin/FGICWebApp/venv/lib/python3.10/site-packages/eodag_sentinelsat/providers.yml
[2025-02-06T09:37:07.329+0000] {config.py:251} DEBUG - Loading configuration from /home/ladsadmin/FGICWebApp/venv/lib/python3.10/site-packages/eodag_sentinelsat/providers.yml
[2025-02-06T09:37:07.359+0000] {config.py:312} INFO - Loading user configuration from: /home/ladsadmin/.config/eodag/eodag.yml
[2025-02-06T09:37:07.360+0000] {logging_mixin.py:154} WARNING - 2025-02-06 09:37:07,359 eodag.config                     [INFO    ] (tid=139875640009152) Loading user configuration from: /home/ladsadmin/.config/eodag/eodag.yml
[2025-02-06T09:37:07.378+0000] {logging_mixin.py:154} WARNING - 2025-02-06 09:37:07,378 eodag.core                       [INFO    ] (tid=139875640009152) usgs: provider needing auth for search has been pruned because no crendentials could be found
[2025-02-06T09:37:07.378+0000] {core.py:376} INFO - usgs: provider needing auth for search has been pruned because no crendentials could be found
[2025-02-06T09:37:07.378+0000] {logging_mixin.py:154} WARNING - 2025-02-06 09:37:07,378 eodag.core                       [INFO    ] (tid=139875640009152) aws_eos: provider needing auth for search has been pruned because no crendentials could be found
[2025-02-06T09:37:07.378+0000] {core.py:404} INFO - aws_eos: provider needing auth for search has been pruned because no crendentials could be found
[2025-02-06T09:37:07.385+0000] {logging_mixin.py:154} WARNING - 2025-02-06 09:37:07,385 eodag.core                       [INFO    ] (tid=139875640009152) meteoblue: provider needing auth for search has been pruned because no crendentials could be found
[2025-02-06T09:37:07.385+0000] {core.py:404} INFO - meteoblue: provider needing auth for search has been pruned because no crendentials could be found
[2025-02-06T09:37:07.385+0000] {logging_mixin.py:154} WARNING - 2025-02-06 09:37:07,385 eodag.core                       [INFO    ] (tid=139875640009152) hydroweb_next: provider needing auth for search has been pruned because no crendentials could be found
[2025-02-06T09:37:07.385+0000] {core.py:404} INFO - hydroweb_next: provider needing auth for search has been pruned because no crendentials could be found
[2025-02-06T09:37:07.385+0000] {logging_mixin.py:154} WARNING - 2025-02-06 09:37:07,385 eodag.core                       [INFO    ] (tid=139875640009152) wekeo: provider needing auth for search has been pruned because no crendentials could be found
[2025-02-06T09:37:07.385+0000] {core.py:404} INFO - wekeo: provider needing auth for search has been pruned because no crendentials could be found
[2025-02-06T09:37:07.392+0000] {logging_mixin.py:154} WARNING - 2025-02-06 09:37:07,392 eodag.core                       [DEBUG   ] (tid=139875640009152) Opening product types index in /home/ladsadmin/.config/eodag/.index
[2025-02-06T09:37:07.392+0000] {core.py:209} DEBUG - Opening product types index in /home/ladsadmin/.config/eodag/.index
[2025-02-06T09:37:07.411+0000] {logging_mixin.py:154} WARNING - 2025-02-06 09:37:07,411 eodag.core                       [INFO    ] (tid=139875640009152) Locations configuration loaded from /home/ladsadmin/.config/eodag/locations.yml
[2025-02-06T09:37:07.411+0000] {core.py:453} INFO - Locations configuration loaded from /home/ladsadmin/.config/eodag/locations.yml
[2025-02-06T09:37:07.420+0000] {_base_logger.py:66} DEBUG - {"worker": "SentinelImageTileService", "msg": "Deserialize data from temporary file.", "level": "DEBUG", "source_data": "S2B_MSIL1C_20240714T065619_N0510_R063_T40QBM_20240714T084853.zip", "sat_image_tile": "SatelliteImageTile object (74)"}
[2025-02-06T09:37:07.423+0000] {_base_logger.py:66} DEBUG - {"worker": "SentinelImageTileService", "msg": "Temporary file deleted: /tmp/tmp33u5pbgt", "level": "DEBUG", "source_data": "S2B_MSIL1C_20240714T065619_N0510_R063_T40QBM_20240714T084853.zip", "sat_image_tile": "SatelliteImageTile object (74)"}
[2025-02-06T09:37:07.425+0000] {_base_logger.py:66} DEBUG - {"worker": "SentinelImageTileService", "msg": "Incrementing download attempts for satellite image tile.", "level": "DEBUG", "source_data": "S2B_MSIL1C_20240714T065619_N0510_R063_T40QBM_20240714T084853.zip", "sat_image_tile": "SatelliteImageTile object (74)"}
[2025-02-06T09:37:07.426+0000] {_base_logger.py:66} DEBUG - {"worker": "SentinelImageTileService", "msg": "Saving download start time for satellite image tile.", "level": "DEBUG", "source_data": "S2B_MSIL1C_20240714T065619_N0510_R063_T40QBM_20240714T084853.zip", "sat_image_tile": "SatelliteImageTile object (74)"}
[2025-02-06T09:37:07.431+0000] {taskinstance.py:1937} ERROR - Task failed with exception
Traceback (most recent call last):
  File "/home/ladsadmin/FGICWebApp/venv/lib/python3.10/site-packages/airflow/decorators/base.py", line 221, in execute
    return_value = super().execute(context)
  File "/home/ladsadmin/FGICWebApp/venv/lib/python3.10/site-packages/airflow/operators/python.py", line 192, in execute
    return_value = self.execute_callable()
  File "/home/ladsadmin/FGICWebApp/venv/lib/python3.10/site-packages/airflow/operators/python.py", line 209, in execute_callable
    return self.python_callable(*self.op_args, **self.op_kwargs)
  File "/home/ladsadmin/FGICWebApp/Airflow/dags/b2_sat_download_worker.py", line 37, in sat_download_sub_worker
    worker.start(sat_image_tile)
  File "/home/ladsadmin/FGICWebApp/SatProductCurator/workers/sat_download_worker.py", line 190, in start
    self.process_started_worker(sat_image_tile)
  File "/home/ladsadmin/FGICWebApp/SatProductCurator/workers/sat_download_worker.py", line 161, in process_started_worker
    service.download(sat_image_tile, source_data)
  File "/home/ladsadmin/FGICWebApp/SatProductCurator/services/satellite_image_tile_service.py", line 65, in download
    is_downloaded = sentinel_service.download(
  File "/home/ladsadmin/FGICWebApp/SatProductCurator/services/sentinel_tile_service.py", line 258, in download
    dag.download(results[0], extract=False)
  File "/home/ladsadmin/FGICWebApp/venv/lib/python3.10/site-packages/eodag/api/core.py", line 1943, in download
    path = product.download(
  File "/home/ladsadmin/FGICWebApp/venv/lib/python3.10/site-packages/eodag/api/product/_product.py", line 319, in download
    self.downloader_auth.authenticate()
  File "/home/ladsadmin/FGICWebApp/venv/lib/python3.10/site-packages/eodag/plugins/authentication/keycloak.py", line 98, in authenticate
    self.validate_config_credentials()
  File "/home/ladsadmin/FGICWebApp/venv/lib/python3.10/site-packages/eodag/plugins/authentication/keycloak.py", line 85, in validate_config_credentials
    super(KeycloakOIDCPasswordAuth, self).validate_config_credentials()
  File "/home/ladsadmin/FGICWebApp/venv/lib/python3.10/site-packages/eodag/plugins/authentication/base.py", line 50, in validate_config_credentials
    raise MisconfiguredError(
eodag.utils.exceptions.MisconfiguredError: The following credentials are missing for provider cop_dataspace: username, password
[2025-02-06T09:37:07.433+0000] {taskinstance.py:844} DEBUG - Refreshing TaskInstance <TaskInstance: B2_Sat_Download_Worker.sat_download_sub_worker manual__2025-02-06T09:36:55.136711+00:00 map_index=0 [running]> from DB
[2025-02-06T09:37:07.453+0000] {taskinstance.py:2430} DEBUG - Task Duration set to 3.603784
[2025-02-06T09:37:07.454+0000] {taskinstance.py:1458} DEBUG - Clearing next_method and next_kwargs.
[2025-02-06T09:37:07.454+0000] {taskinstance.py:1400} INFO - Marking task as FAILED. dag_id=B2_Sat_Download_Worker, task_id=sat_download_sub_worker, map_index=0, execution_date=20250206T093655, start_date=20250206T093703, end_date=20250206T093707
[2025-02-06T09:37:07.469+0000] {cli_action_loggers.py:85} DEBUG - Calling callbacks: []
[2025-02-06T09:37:07.470+0000] {standard_task_runner.py:104} ERROR - Failed to execute job 303503 for task sat_download_sub_worker (The following credentials are missing for provider cop_dataspace: username, password; 2332531)
[2025-02-06T09:37:07.512+0000] {local_task_job_runner.py:228} INFO - Task exited with return code 1
[2025-02-06T09:37:07.540+0000] {dagrun.py:734} DEBUG - number of tis tasks for <DagRun B2_Sat_Download_Worker @ 2025-02-06 09:36:55.136711+00:00: manual__2025-02-06T09:36:55.136711+00:00, state:running, queued_at: 2025-02-06 09:36:55.173711+00:00. externally triggered: True>: 0 task(s)
[2025-02-06T09:37:07.541+0000] {taskinstance.py:2778} INFO - 0 downstream tasks scheduled from follow-on schedule check
